Workbook

Sheet Abs. - L&T
B2: APPLICATION FOR INTERIM PAYMENT
B3: ABSTRACT SHEET
B4: Interim Payment Application No. : | D4: IPA - 34 | G4: Bill date : | H4: =TODAY()-1 -> 46285
B5: Type of Work : | D5: ='Abs. - PMC (For Print)'!D5 -> Main Works & Price Adjustment
B6: Period of bill : | D6: ='Abs. - PMC (For Print)'!D6 -> 1st Jul'26 to 31st Jul'26
B7: EPC Contractor : | D7: Larsen and Toubro Limited
B8: Address: | D8: L&T Construction, Majirgaon Palashbari - Sualkuchi Bridge Project, Dag No. 268 & 269, Patta No. 43 & 168, Revenue Village - Santala, Revenue Circle - Palashbari, Kamrup District, Assam - 781125.
B9: Employer : | D9: The Chief Engineer (EAP), Public Works Roads Department (PWRD), Assam
B10: Employer's Representative : | D10: Rodic Consultants Private Limited in JV with Intercontinental Consultants and Technocrats Private Limited
B11: LOA Ref. No. : | D11: CE/EAP/ABP-II/EPC/OCB/2023/35 | G11: Contract Value (INR) : | H11: =26885400000 -> 26885400000
B12: Work Order No : | D12: Contract Agreement signed on 01-Mar-24 | G12: Financial Progress: | H12: ='Breakup-Summary'!$F$23 -> 0.75762732
B13: Name of Work : | D13: Construction of 4-lane Extradosed PSC Bridge over river Brahmaputra connecting Palashbari and Sualkuchi including Viaduct, Approaches and River Training works etc on EPC mode
B14: S.No. | C14: Description | E14: Currency | F14: Amount
F15: Cumulative Bill | G15: Up to Previous Bill | H15: This Bill
B16: A | C16: Work Done
B17: a | C17: Amount for the works executed under Sub-Clause 14.3 of the General Conditions | E17: =_xlfn.UNICHAR(8377) -> ₹ | F17: =('Detailed breakup'!N531/1.18) -> 1.7226391e+10 | G17: =('Detailed breakup'!P531/1.18) -> 1.1013076e+10 | H17: =F17-G17 -> 6.2133151e+09
B18: b | C18: Amount for the Provisional Sum under Sub-Clause 13.4 of the General Conditions | E18: ₹ | F18: =('Detailed breakup'!N532/1.18) -> 1369786.4 | G18: =('Detailed breakup'!P532/1.18) -> 1369786.4 | H18: =F18-G18 -> 0
B19: c | C19: Amount reflecting Changes in Cost under Sub-Clause 13.7 of the General Conditions | E19: ₹ | F19: =('Price Adj.'!V75/1.18) -> 3.1668907e+08 | G19: =('Price Adj.'!V76/1.18) -> 60193167 | H19: =F19-G19 -> 2.564959e+08
B20: d | C20: Amount of Variation Order executed under Sub-Clause 13.3 of the General Conditions | E20: ₹ | F20: 0 | G20: 0 | H20: =F20-G20 -> 0
B21: e | C21: Amount reflecting Change in Law under Sub-Clause 13.6 of the General Conditions | E21: ₹ | F21: 0 | G21: 0 | H21: =F21-G21 -> 0
B22: f1 | C22: CGST @ 9% on [Aa to Ae] | E22: ₹ | F22: =(SUM($F$17:$F$21)*9%) -> 1.5790005e+09 | G22: =(SUM($G$17:$G$21)*9%) -> 9.9671747e+08 | H22: =ROUND(SUM($H$17:$H$21)*9%,0) -> 582282989
B23: f2 | C23: SGST @ 9% on [Aa to Ae] | E23: ₹ | F23: =(SUM($F$17:$F$21)*9%) -> 1.5790005e+09 | G23: =(SUM($G$17:$G$21)*9%) -> 9.9671747e+08 | H23: =ROUND(SUM($H$17:$H$21)*9%,0) -> 582282989
C24: Total Work Done (A) = (Aa+Ab+Ac+Ad+Ae+Af1+Af2) | E24: ₹ | F24: =SUM(F17:F23) -> 2.070245e+10 | G24: =SUM(G17:G23) -> 13068073432 | H24: =SUM(H17:H23) -> 7.634377e+09
C25: Total Work Done (Excl. of taxes) (A1) = (A/1.18) | E25: ₹ | F25: =F24/1.18 -> 1.7544449e+10 | G25: =G24/1.18 -> 1.1074639e+10 | H25: =H24/1.18 -> 6.469811e+09
B26: B | C26: Advances
B27: a | C27: Mobilization Advance under Sub-Clause 14.2 of General Condidtions - 1st Installment | E27: ₹ | F27: =G27+H27 -> 1.1392119e+09 | G27: =(H11*5%/1.18) -> 1.1392119e+09 | H27: 0
B28: b | C28: Mobilization Advance under Sub-Clause 14.2 of General Condidtions - 2nd Installment | E28: ₹ | F28: =H28+G28 -> 1.1392119e+09 | G28: =(H11*5%/1.18) -> 1.1392119e+09 | H28: 0
B29: c1 | C29: CGST @ 9% on [Ba to Bb] | E29: ₹ | F29: =(SUM($F$27:$F$28)*9%) -> 2.0505814e+08 | G29: =(SUM($G$27:$G$28)*9%) -> 2.0505814e+08 | H29: =SUM($H$27:$H$28)*9% -> 0
B30: c2 | C30: SGST @ 9% on [Ba to Bb] | E30: ₹ | F30: =ROUND(SUM($F$27:$F$28)*9%,0) -> 205058136 | G30: =(SUM($G$27:$G$28)*9%) -> 2.0505814e+08 | H30: =SUM($H$27:$H$28)*9% -> 0
C31: Total Advances (B) = (Ba+Bb+Bc1+Bc2) | E31: ₹ | F31: =SUM(F27:F30) -> 2.68854e+09 | G31: =SUM(G27:G30) -> 2688540000 | H31: =SUM(H27:H30) -> 0
C32: Gross Amount (Incl. Advances) (B1) = (A+B) | E32: ₹ | F32: =F31+F24 -> 2.339099e+10 | G32: =G31+G24 -> 15756613432 | H32: =H31+H24 -> 7.634377e+09
C33: Gross Amount (Excl. Taxes) (B2) = (B1/1.18) | E33: ₹ | F33: =ROUND(F32/1.18,0) -> 19822873220 | G33: =ROUND(G32/1.18,0) -> 13353062231 | H33: =ROUND(H32/1.18,0) -> 6469810989
B34: C | C34: Recoveries
B35: a | C35: Mobilization Advance under Sub-Clause 14.2 of General Condidtions @ 15% on [A1] | E35: ₹ | F35: =G35+H35 -> 2.5841641e+09 | G35: =(SUM(G17:G18)*15%) -> 1.6521668e+09 | H35: =(SUM(H17:H18)*15%) -> 9.3199726e+08
B36: b1 | C36: CGST @ 9% on [Ca] | E36: ₹ | F36: =SUM($F$35:$F$35)*9% -> 2.3257477e+08 | G36: =(SUM($G$35:$G$35)*9%) -> 1.4869501e+08 | H36: =(SUM($H$35:$H$35)*9%) -> 83879754
B37: b2 | C37: SGST @ 9% on [Ca] | E37: ₹ | F37: =SUM($F$35:$F$35)*9% -> 2.3257477e+08 | G37: =(SUM($G$35:$G$35)*9%) -> 1.4869501e+08 | H37: =(SUM($H$35:$H$35)*9%) -> 83879754
C38: Total Recoveries (C) = (Ca+Cb1+Cb2) | E38: ₹ | F38: =SUM(F35:F37) -> 3.0493136e+09 | G38: =SUM(G35:G37) -> 1.9495568e+09 | H38: =SUM(H35:H37) -> 1.0997568e+09
B39: D | C39: Withheld / Release
B40: a | C40: Retention Amount @ 6% upto 5% of Contract Value on [A] | E40: ₹ | F40: =IF((G40+H40)<="5%*$H$11",(G40+H40),5%*$H$11) -> 1.242147e+09 | G40: =G24*6% -> 7.8408441e+08 | H40: =H24*6% -> 4.5806262e+08
B41: b | C41: Release of Retention Amount | E41: ₹ | F41: =G41+H41 -> -605998256 | G41: =-'Retention Release'!$G$39 -> -605998256 | H41: =-'Retention Release'!$G$40 -> 0
...

Sheet Abs. - PMC
B2: INTERIM PAYMENT CERTIFICATION
B3: ABSTRACT SHEET
B4: Interim Payment Certificate No. : | D4: IPC - 15 | G4: Bill date : | H4: 45799
B5: Type of Work : | D5: Main Works and Price Adjustment
B6: Period of bill : | D6: ='Abs. - L&T'!D6 -> 1st Jul'26 to 31st Jul'26
B7: EPC Contractor : | D7: Larsen and Toubro Limited
B8: Address: | D8: L&T Construction, Majirgaon Palashbari - Sualkuchi Bridge Project, Dag No. 268 & 269, Patta No. 43 & 168, Revenue Village - Santala, Revenue Circle - Palashbari, Kamrup District, Assam - 781125.
B9: Employer : | D9: The Chief Engineer (EAP), Public Works Roads Department (PWRD), Assam
B10: Employer's Representative : | D10: Rodic Consultants Private Limited in JV with Intercontinental Consultants and Technocrats Private Limited
B11: LOA Ref. No. : | D11: CE/EAP/ABP-II/EPC/OCB/2023/35 | G11: Contract Value (INR) : | H11: =26885400000 -> 26885400000
B12: Work Order No : | D12: Contract Agreement signed on 01-Mar-24 | G12: Financial Progress: | H12: =F17/H11 -> 0.75606615
B13: Name of Work : | D13: Construction of 4-lane Extradosed PSC Bridge over river Brahmaputra connecting Palashbari and Sualkuchi including Viaduct, Approaches and River Training works etc on EPC mode
B14: S.No. | C14: Description | E14: Currency | F14: Amount
F15: Cumulative Bill | G15: Up to Previous Bill | H15: This Bill
B16: A | C16: Work Done
B17: a | C17: Amount for the works executed under Sub-Clause 14.3 of the General Conditions | E17: =_xlfn.UNICHAR(8377) -> ₹ | F17: ='Detailed breakup'!N531 -> 20327140948 | G17: ='Detailed breakup'!P531 -> 12995429147 | H17: =F17-G17 -> 7331711801
B18: b | C18: Amount for the Provisional Sum under Sub-Clause 13.4 of the General Conditions | E18: =_xlfn.UNICHAR(8377) -> ₹ | F18: ='Detailed breakup'!N532 -> 1616348 | G18: ='Detailed breakup'!P532 -> 1616348 | H18: ='Detailed breakup'!R532 -> 0
B19: c | C19: Amount reflecting Changes in Cost under Sub-Clause 13.7 of the General Conditions | E19: =_xlfn.UNICHAR(8377) -> ₹ | F19: ='Price Adj.'!V75 -> 373693103 | G19: ='Price Adj.'!V76 -> 71027937 | H19: =F19-G19 -> 302665166
B20: d | C20: Amount of Variation Order executed under Sub-Clause 13.3 of the General Conditions | E20: =_xlfn.UNICHAR(8377) -> ₹ | F20: 0 | G20: 0 | H20: =F20-G20 -> 0
B21: e | C21: Amount reflecting Change in Law under Sub-Clause 13.6 of the General Conditions | E21: =_xlfn.UNICHAR(8377) -> ₹ | F21: 0 | G21: 0 | H21: =F21-G21 -> 0
C22: Total Work Done (A) = (Aa+Ab+Ac+Ad+Ae) | E22: =_xlfn.UNICHAR(8377) -> ₹ | F22: =(SUM(F17:F21)) -> 20702450399 | G22: =(SUM(G17:G21)) -> 13068073432 | H22: =(SUM(H17:H21)) -> 7634376967
C23: Total Work Done (Excl. of Taxes) (A1) = (A/1.18) | E23: =_xlfn.UNICHAR(8377) -> ₹ | F23: =(F22/1.18) -> 1.7544449e+10 | G23: =(G22/1.18) -> 1.1074639e+10 | H23: =(H22/1.18) -> 6.469811e+09
B24: B | C24: Advances
B25: a | C25: Mobilization Advance under Sub-Clause 14.2 of General Condidtions - 1st Installment | E25: ₹ | F25: =G25+H25 -> 2688540000 | G25: =H11*10% -> 2688540000 | H25: 0
B26: b | C26: Mobilization Advance under Sub-Clause 14.2 of General Condidtions - 2nd Installment | E26: ₹ | F26: =H26+G26 -> 0 | G26: 0 | H26: 0
C27: Total Advances (B) = (Ba+Bb) | E27: ₹ | F27: =(SUM(F25:F26)) -> 2688540000 | G27: =(SUM(G25:G26)) -> 2688540000 | H27: =(SUM(H25:H26)) -> 0
C28: Gross Amount due including Advances (B1) = (A+B) | E28: ₹ | F28: =(F22+F27) -> 23390990399 | G28: =(G22+G27) -> 15756613432 | H28: =(H22+H27) -> 7634376967
C29: Gross Amount (Excl. of Taxes) (B2) = (B1/1.18) | E29: ₹ | F29: =(F28/1.18) -> 1.9822873e+10 | G29: =(G28/1.18) -> 1.3353062e+10 | H29: =(H28/1.18) -> 6.469811e+09
B30: C | C30: Recoveries
B31: a | C31: Mobilization Advance under Sub-Clause 14.2 of General Condidtions @ 15% on [A] | E31: ₹ | F31: =(G31+H31) -> 3.1053676e+09 | G31: =(G22*15%) -> 1.960211e+09 | H31: =(H22*15%) -> 1.1451565e+09
B32: b | C32: Retention Amount @ 6% upto 5% of Contract Value on [A] | E32: ₹ | F32: =(G32+H32) -> 1.242147e+09 | G32: =(G22*6%) -> 7.8408441e+08 | H32: =(H22*6%) -> 4.5806262e+08
C33: Total Recoveries (C) = (Ca+Cb) | E33: ₹ | F33: =SUM(F31:F32) -> 4.3475146e+09 | G33: =SUM(G31:G32) -> 2.7442954e+09 | H33: =SUM(H31:H32) -> 1.6032192e+09
C34: Amount due before Taxes (C1) = (B1-C) | E34: ₹ | F34: =F28-F33 -> 1.9043476e+10 | G34: =G28-G33 -> 1.3012318e+10 | H34: =H28-H33 -> 6.0311578e+09
B35: D | C35: Withheld
B36: a | C36: Withheld Amount | E36: ₹ | F36: =G36+H36 -> 0 | G36: 0 | H36: 0
B37: b | C37: Release of Withheld Amount | E37: ₹ | F37: =G37+H37 -> 0 | G37: 0 | H37: 0
C38: Total Advances (D) = (Da+Db) | E38: ₹ | F38: =SUM(F36:F37) -> 0 | G38: =SUM(G36:G37) -> 0 | H38: =SUM(H36:H37) -> 0
C39: Taxable Amount (D1) = ((A-Ca)/1.18) | E39: ₹ | F39: =((F22-F31)/1.18) -> 1.4912782e+10 | G39: =((G22-G31)/1.18) -> 9.4134427e+09 | H39: =((H22-H31)/1.18) -> 5.4993393e+09
B40: E | C40: Deductions
B41: a | C41: Income tax @ 2% on [(B+(A-Ca))/1.18] | E41: ₹ | F41: =((F27+F22-F31)/1.18*2%) -> 3.4382412e+08 | G41: 64838315 | H41: =F41-G41 -> 2.789858e+08
...

Sheet Abs. - PMC (For Print)
B2: INTERIM PAYMENT CERTIFICATION
B3: ABSTRACT SHEET
B4: Interim Payment Certificate No. : | D4: IPC - 34 | G4: Bill date : | H4: =TODAY()-1 -> 46285
B5: Type of Work : | D5: Main Works & Price Adjustment
B6: Period of bill : | D6: 1st Jul'26 to 31st Jul'26
B7: EPC Contractor : | D7: Larsen and Toubro Limited
B8: Address: | D8: L&T Construction, Majirgaon Palashbari - Sualkuchi Bridge Project, Dag No. 268 & 269, Patta No. 43 & 168, Revenue Village - Santala, Revenue Circle - Palashbari, Kamrup District, Assam - 781125.
B9: Employer : | D9: The Chief Engineer (EAP), Public Works Roads Department (PWRD), Assam
B10: Employer's Representative : | D10: Rodic Consultants Private Limited in JV with Intercontinental Consultants and Technocrats Private Limited
B11: LOA Ref. No. : | D11: CE/EAP/ABP-II/EPC/OCB/2023/35 | G11: Contract Value (INR) : | H11: =26885400000 -> 26885400000
B12: Work Order No : | D12: Contract Agreement signed on 01-Mar-24 | G12: Financial Progress: | H12: ='Breakup-Summary'!$F$23 -> 0.75762732
B13: Name of Work : | D13: Construction of 4-lane Extradosed PSC Bridge over river Brahmaputra connecting Palashbari and Sualkuchi including Viaduct, Approaches and River Training works etc on EPC mode
B14: S.No. | C14: Description | E14: Currency | F14: Amount
F15: Cumulative Bill | G15: Up to Previous Bill | H15: This Bill
B16: A | C16: Work Done
B17: a | C17: Amount for the works executed under Sub-Clause 14.3 of the General Conditions | E17: ₹ | F17: ='Detailed breakup'!$N$531 -> 20327140948 | G17: ='Detailed breakup'!$P$531 -> 12995429147 | H17: =F17-G17 -> 7331711801
B18: b | C18: Amount for the Provisional Sum under Sub-Clause 13.4 of the General Conditions | E18: ₹ | F18: ='Detailed breakup'!N532 -> 1616348 | G18: ='Detailed breakup'!P532 -> 1616348 | H18: ='Detailed breakup'!R532 -> 0
B19: c | C19: Amount reflecting Changes in Cost under Sub-Clause 13.7 of the General Conditions | E19: ₹ | F19: ='Price Adj.'!$V$75 -> 373693103 | G19: ='Price Adj.'!$V$76 -> 71027937 | H19: =F19-G19 -> 302665166
B20: d | C20: Amount of Variation Order executed under Sub-Clause 13.3 of the General Conditions | E20: ₹ | F20: 0 | G20: 0 | H20: =F20-G20 -> 0
B21: e | C21: Amount reflecting Change in Law under Sub-Clause 13.6 of the General Conditions | E21: ₹ | F21: 0 | G21: 0 | H21: =F21-G21 -> 0
C22: Total Work Done (A) = (Aa+Ab+Ac+Ad+Ae) | E22: ₹ | F22: =(SUM(F17:F21)) -> 20702450399 | G22: =(SUM(G17:G21)) -> 13068073432 | H22: =(SUM(H17:H21)) -> 7634376967
B23: B | C23: Advances / Recovery
B24: a | C24: Mobilization Advance under Sub-Clause 14.2 of General Conditions - 1st Installment | E24: ₹ | F24: =G24+H24 -> 1344270000 | G24: =H11*5% -> 1344270000 | H24: 0
B25: b | C25: Mobilization Advance under Sub-Clause 14.2 of General Conditions - 2nd Installment | E25: ₹ | F25: =G25+H25 -> 1344270000 | G25: =H11*5% -> 1344270000 | H25: 0
B26: c | C26: Recovery of Mob. Advance under Sub-Clause 14.2 of GC @ 15% on [Aa+Ab] | E26: ₹ | F26: =ROUND((F17+F18)*15%,0) -> 3049313594 | G26: =ROUND((G17+G18)*15%,0) -> 1949556824 | H26: =F26-G26 -> 1099756770
C27: Total Advances (B) = (Ba+Bb-Bc) | E27: ₹ | F27: =F24+F25-F26 -> -360773594 | G27: =G24+G25-G26 -> 738983176 | H27: =H24+H25-H26 -> -1099756770
C28: Gross Amount due including Advances (B1) = (A+B) | E28: ₹ | F28: =(F22+F27) -> 20341676805 | G28: =(G22+G27) -> 13807056608 | H28: =(H22+H27) -> 6534620197
C30: Taxable Amount (B2) = ((A+B)/1.18) | E30: ₹ | F30: =ROUND((F22+F27)/1.18,0) -> 17238709157 | G30: =ROUND((G22+G27)/1.18,0) -> 11700895431 | H30: =ROUND((H22+H27)/1.18,0) -> 5537813726
B31: C | C31: Recovery / Release
B32: a | C32: Recovery of Retention Amount @ 6% upto 5% of Contract Value on [A] | E32: ₹ | F32: =ROUND((F22)*6%,0) -> 1242147024 | G32: =ROUND((G22*6%),0) -> 784084406 | H32: =F32-G32 -> 458062618
B33: b | C33: Release of Retention Amount against Bank Guarantee | E33: ₹ | F33: =-'Retention Release'!$G$38 -> -605998256 | G33: =-'Retention Release'!$G$39 -> -605998256 | H33: =F33-G33 -> 0
C34: Total Recovery (C) = (Ca+Cb) | E34: ₹ | F34: =SUM(F32:F33) -> 636148768 | G34: =SUM(G32:G33) -> 178086150 | H34: =SUM(H32:H33) -> 458062618
C35: Amount due before Taxes (C1) = (B1-C) | E35: ₹ | F35: =F28-F34 -> 19705528037 | G35: =G28-G34 -> 13628970458 | H35: =H28-H34 -> 6076557579
B36: D | C36: Withheld / Release
B37: a | C37: Withheld Amount | E37: ₹ | F37: =ROUND('Withheld-Release'!$M$46,0) -> 497964247 | G37: =ROUND('Withheld-Release'!$M$47,0) -> 497964247 | H37: =F37-G37 -> 0
B38: b | C38: Release of Withhled Amount | E38: ₹ | F38: =-ROUND('Withheld-Release'!$R$46,0) -> -497964247 | G38: =-ROUND('Withheld-Release'!R47,0) -> -497964247 | H38: =F38-G38 -> 0
C39: Total Withheld (D) = (Da+Db) | E39: ₹ | F39: =SUM(F37:F38) -> 0 | G39: =SUM(G37:G38) -> 0 | H39: =SUM(H37:H38) -> 0
C40: Amount due before Taxes after withheld (D1) = (C1-D) | E40: ₹ | F40: =F35-F39 -> 19705528037 | G40: =G35-G39 -> 13628970458 | H40: =H35-H39 -> 6076557579
B41: E | C41: Deductions
B42: a | C42: TDS - Income tax @ 2% on [B2] | E42: ₹ | J42: =ROUND((F30*2%),0) -> 344774183 | K42: 227561965 | L42: =ROUND((H30*2%),0) -> 110756275 | N42: =O42+P42 -> 338318240 | O42: =K42 -> 227561965 | P42: =L42 -> 110756275
...

Sheet Breakup-Summary
C2: Construction of 4-lane Extra-dosed PSC Bridge over river Brahmaputra connecting Palashbari and Sualkuchi including Viaduct, Approaches and River Training works etc on EPC mode
B3: General Conditions of Contract - Clause 14.4 - Summary - Schedule of Payments
B4: Schedule No | C4: Description | D4: Schedule Cost (% of the Contract Price) | F4: Cumulative Bill | H4: Up to Previous Bill | J4: This Bill (INR)
D5: Weightage % | E5: Amount (INR) | F5: Weightage % | G5: Amount (Rs.) | H5: Weightage % | I5: Amount (Rs.) | J5: Weightage % | K5: Amount (Rs.)
B7: Schedule 1 | C7: Preliminaries & General Items | D7: 0.025 | E7: =D7*(26885400000-55400000) -> 670750000 | F7: =G7/$E7*$D7 -> 0.019109844 | G7: ='Detailed breakup'!N119 -> 512717121 | H7: =I7/$E7*$D7 -> 0.019109844 | I7: ='Detailed breakup'!P119 -> 512717121 | J7: =K7/$E7*$D7 -> 0 | K7: ='Detailed breakup'!R119 -> 0
B9: Schedule 2 | C9: Validation of Survey Data, Investigation, Design and As-Built Drawings | D9: 0.03 | E9: =D9*(26885400000-55400000) -> 804900000 | F9: =G9/$E9*$D9 -> 0.027275441 | G9: ='Detailed breakup'!N275 -> 731800089 | H9: =I9/$E9*$D9 -> 0.027244691 | I9: ='Detailed breakup'!P275 -> 730975066 | J9: =K9/$E9*$D9 -> 3.0750019e-05 | K9: ='Detailed breakup'!R275 -> 825023
B11: Schedule 3 | C11: Enabling Works for Main Works | D11: 0.045 | E11: =D11*(26885400000-55400000) -> 1207350000 | F11: =G11/$E11*$D11 -> 0.04149 | G11: ='Detailed breakup'!N313 -> 1113176703 | H11: =I11/$E11*$D11 -> 0.04149 | I11: ='Detailed breakup'!P313 -> 1113176703 | J11: =K11/$E11*$D11 -> 0 | K11: ='Detailed breakup'!R313 -> 0
B13: Schedule 4 | C13: Main Extradosed Bridge Works | D13: 0.67 | E13: =D13*(26885400000-55400000) -> 17976100000 | F13: =G13/$E13*$D13 -> 0.53041941 | G13: ='Detailed breakup'!N376 -> 14231152805 | H13: =I13/$E13*$D13 -> 0.26078233 | I13: ='Detailed breakup'!P376 -> 6996789931 | J13: =K13/$E13*$D13 -> 0.26963708 | K13: ='Detailed breakup'!R376 -> 7234362874
B15: Schedule 5 | C15: Wetland and Approach Viaduct Works | D15: 0.145 | E15: =D15*(26885400000-55400000) -> 3.89035e+09 | F15: =G15/$E15*$D15 -> 0.10913714 | G15: ='Detailed breakup'!N459 -> 2928149367 | H15: =I15/$E15*$D15 -> 0.10565219 | I15: ='Detailed breakup'!P459 -> 2834648310 | J15: =K15/$E15*$D15 -> 0.0034849444 | K15: ='Detailed breakup'!R459 -> 93501057
B17: Schedule 6 | C17: Underpass Works | D17: 0.025 | E17: =D17*(26885400000-55400000) -> 670750000 | F17: =G17/$E17*$D17 -> 0.022104 | G17: ='Detailed breakup'!N491 -> 593050320 | H17: =I17/$E17*$D17 -> 0.022104 | I17: ='Detailed breakup'!P491 -> 593050320 | J17: =K17/$E17*$D17 -> 0 | K17: ='Detailed breakup'!R491 -> 0
B19: Schedule 7 | C19: Approach road Works | D19: 0.06 | E19: =D19*(26885400000-55400000) -> 1609800000 | F19: =G19/$E19*$D19 -> 0.008091485 | G19: ='Detailed breakup'!N517 -> 217094543 | H19: =I19/$E19*$D19 -> 0.0079788183 | I19: ='Detailed breakup'!P517 -> 214071696 | J19: =K19/$E19*$D19 -> 0.00011266668 | K19: ='Detailed breakup'!R517 -> 3022847
B21: Schedule 8 | C21: Provisional Sum | E21: =55400000 -> 55400000 | G21: ='Detailed breakup'!N529 -> 1616348 | I21: ='Detailed breakup'!P529 -> 1616348 | K21: ='Detailed breakup'!R529 -> 0
C23: Total | D23: =SUM(D6:D22) -> 1 | E23: =SUM(E7:E22) -> 26885400000 | F23: =SUM(F7:F21) -> 0.75762732 | G23: =SUM(G7:G22) -> 20328757296 | H23: =SUM(H7:H22) -> 0.48436188 | I23: =SUM(I7:I22) -> 12997045495 | J23: =SUM(J7:J21) -> 0.27326544 | K23: =SUM(K7:K22) -> 7331711801 | L23: 339313902 | M23: =K23-L23 -> 6992397899
E25: =E21/10^7 -> 5.54
K26: =K23*0.73 -> 5.3521496e+09
K27: =SUM('Royalty Details'!G55:J58) -> 7392224
K28: 11700000
K30: =SUM(K26:K29) -> 5.3712418e+09
D73: PL1 - Piercap - WV1
D74: PL2 - Piercap - WV1
D75: PR3 - Piercap - WV1
D76: PR1 - Piercap - WV1
D77: PL3 - Piercap - WV1
D78: PR2 - Piercap - WV1
D79: PL0 - Piercap - WV1
D80: PR0 - Piercap - WV1

Sheet Detailed breakup
C2: Construction of 4-lane Extra-dosed PSC Bridge over river Brahmaputra connecting Palashbari and Sualkuchi including Viaduct, Approaches and River Training works etc on EPC mode
B3: General Conditions of Contract - Clause 14.4 - Schedule of Payments
O4: ='Abs. - PMC'!B6 -> Period of bill : | Q4: ='Abs. - PMC'!D6 -> 1st Jul'26 to 31st Jul'26
B5: Schedule No | C5: Description | D5: Schedule Cost (% of the Contract Price) | F5: Item No | G5: Item Description | H5: UOM | I5: Percentage | J5: Tentative Scope | K5: Amount (INR) | L5: Amount payable per Unit (INR) | M5: Cumulative Bill | O5: Upto Previous Bill | Q5: This Bill | T5: Measurement Book
D6: Weightage % | E6: Amount (INR) | M6: Quantity | N6: Amount (INR) | O6: Quantity | P6: Amount (INR) | Q6: Quantity | R6: Amount (INR) | T6: Page | U6: No
B8: Schedule 1 | C8: Preliminaries & General Items | D8: 0.025 | E8: =D8*(26885400000-55400000) -> 670750000 | F8: 101 | G8: Provision (construction) of office facilities for the Employer | H8: LS | I8: 0.305 | K8: =I8*$E$8 -> 204578750
F9: a | G9: Completion of Foundation | H9: Nos. | I9: 0.2 | J9: 2 | K9: =I9*$K$8 -> 40915750 | L9: =IFERROR(K9/J9,0) -> 20457875 | M9: ='Schedule 1'!F14 -> 2 | N9: =ROUND(L9*M9,0) -> 40915750 | O9: ='Schedule 1'!F15 -> 2 | P9: 40915750 | Q9: =M9-O9 -> 0 | R9: =N9-P9 -> 0 | S9: =J9-M9 -> 0
F10: b | G10: Completion of Plinth | H10: Nos. | I10: 0.18 | J10: 2 | K10: =I10*$K$8 -> 36824175 | L10: =IFERROR(K10/J10,0) -> 18412088 | M10: ='Schedule 1'!F21 -> 2 | N10: =(L10*M10) -> 36824175 | O10: ='Schedule 1'!F22 -> 2 | P10: 36824175 | Q10: =M10-O10 -> 0 | R10: =N10-P10 -> 0 | S10: =J10-M10 -> 0
F11: c | G11: Completion of Walls | H11: Nos. | I11: 0.15 | J11: 2 | K11: =I11*$K$8 -> 30686812 | L11: =IFERROR(K11/J11,0) -> 15343406 | M11: ='Schedule 1'!F28 -> 2 | N11: =ROUND(L11*M11,0) -> 30686813 | O11: ='Schedule 1'!F29 -> 2 | P11: 30686813 | Q11: =M11-O11 -> 0 | R11: =N11-P11 -> 0 | S11: =J11-M11 -> 0
F12: d | G12: Completion of Roofs | H12: Nos. | I12: 0.15 | J12: 2 | K12: =I12*$K$8 -> 30686812 | L12: =IFERROR(K12/J12,0) -> 15343406 | M12: ='Schedule 1'!F35 -> 2 | N12: =ROUND(L12*M12,0) -> 30686813 | O12: ='Schedule 1'!F36 -> 2 | P12: 30686813 | Q12: =M12-O12 -> 0 | R12: =N12-P12 -> 0 | S12: =J12-M12 -> 0
F13: e | G13: Completion of Flooring | H13: Nos. | I13: 0.18 | J13: 2 | K13: =I13*$K$8 -> 36824175 | L13: =IFERROR(K13/J13,0) -> 18412088 | M13: ='Schedule 1'!F42 -> 2 | N13: =(L13*M13) -> 36824175 | O13: ='Schedule 1'!F43 -> 2 | P13: 36824175 | Q13: =M13-O13 -> 0 | R13: =N13-P13 -> 0 | S13: =J13-M13 -> 0
F14: f | G14: Completion of Finishing Works | S14: =J14-M14 -> 0
F15: i | G15: Electrical and Sanitary Works | H15: Nos. | I15: 0.1 | J15: 2 | K15: =I15*$K$8 -> 20457875 | L15: =IFERROR(K15/J15,0) -> 10228938 | M15: ='Schedule 1'!F50 -> 2 | N15: =ROUND(L15*M15,0) -> 20457875 | O15: ='Schedule 1'!F51 -> 2 | P15: 20457875 | Q15: =M15-O15 -> 0 | R15: =N15-P15 -> 0 | S15: =J15-M15 -> 0
F16: ii | G16: Office Furniture | S16: =J16-M16 -> 0
F17: 1 | G17: Executive Office Desk | H17: Nos. | I17: 0.0025 | J17: 8 | K17: =I17*$K$8 -> 511446.88 | L17: =IFERROR(K17/J17,0) -> 63930.859 | M17: ='Schedule 1'!F57 -> 8 | N17: =ROUND(L17*M17,0) -> 511447 | O17: ='Schedule 1'!F58 -> 8 | P17: 511447 | Q17: =M17-O17 -> 0 | R17: =N17-P17 -> 0 | S17: =J17-M17 -> 0
F18: 2 | G18: Executive Chairs | H18: Nos. | I18: 0.0025 | J18: 8 | K18: =I18*$K$8 -> 511446.88 | L18: =IFERROR(K18/J18,0) -> 63930.859 | M18: ='Schedule 1'!F64 -> 8 | N18: =ROUND(L18*M18,0) -> 511447 | O18: ='Schedule 1'!F65 -> 8 | P18: 511447 | Q18: =M18-O18 -> 0 | R18: =N18-P18 -> 0 | S18: =J18-M18 -> 0
F19: 3 | G19: Visitor Chairs | H19: Nos. | I19: 0.0015 | J19: 20 | K19: =I19*$K$8 -> 306868.12 | L19: =IFERROR(K19/J19,0) -> 15343.406 | M19: ='Schedule 1'!F68 -> 20 | N19: =ROUND(L19*M19,0) -> 306868 | O19: ='Schedule 1'!F71 -> 20 | P19: 306868 | Q19: =M19-O19 -> 0 | R19: =N19-P19 -> 0 | S19: =J19-M19 -> 0
F20: 4 | G20: Conference Table | H20: Nos. | I20: 0.005 | J20: 2 | K20: =I20*$K$8 -> 1022893.8 | L20: =IFERROR(K20/J20,0) -> 511446.88 | M20: ='Schedule 1'!F74 -> 2 | N20: =ROUND(L20*M20,0) -> 1022894 | O20: ='Schedule 1'!F77 -> 2 | P20: 1022894 | Q20: =M20-O20 -> 0 | R20: =N20-P20 -> 0 | S20: =J20-M20 -> 0
F21: 5 | G21: Conference Chairs | H21: Nos. | I21: 0.005 | J21: 60 | K21: =I21*$K$8 -> 1022893.8 | L21: =IFERROR(K21/J21,0) -> 17048.229 | M21: ='Schedule 1'!F80 -> 60 | N21: =ROUND(L21*M21,0) -> 1022894 | O21: ='Schedule 1'!F83 -> 60 | P21: 1022894 | Q21: =M21-O21 -> 0 | R21: =N21-P21 -> 0 | S21: =J21-M21 -> 0
F22: 6 | G22: Projector and Monitor in Conference room | H22: Nos. | I22: 0.003 | J22: 1 | K22: =I22*$K$8 -> 613736.25 | L22: =IFERROR(K22/J22,0) -> 613736.25 | M22: ='Schedule 1'!F86 -> 1 | N22: =ROUND(L22*M22,0) -> 613736 | O22: ='Schedule 1'!F89 -> 1 | P22: 613736 | Q22: =M22-O22 -> 0 | R22: =N22-P22 -> 0 | S22: =J22-M22 -> 0
F23: 7 | G23: Display Arrangement | H23: Nos. | I23: 0.001 | J23: 2 | K23: =I23*$K$8 -> 204578.75 | L23: =IFERROR(K23/J23,0) -> 102289.38 | M23: ='Schedule 1'!F92 -> 2 | N23: =ROUND(L23*M23,0) -> 204579 | O23: ='Schedule 1'!F95 -> 2 | P23: 204579 | Q23: =M23-O23 -> 0 | R23: =N23-P23 -> 0 | S23: =J23-M23 -> 0
F24: 8 | G24: Steel Almirah and Racks | H24: Nos. | I24: 0.002 | J24: 10 | K24: =I24*$K$8 -> 409157.5 | L24: =IFERROR(K24/J24,0) -> 40915.75 | M24: ='Schedule 1'!F101 -> 10 | N24: =ROUND(L24*M24,0) -> 409158 | O24: ='Schedule 1'!F102 -> 10 | P24: 409158 | Q24: =M24-O24 -> 0 | R24: =N24-P24 -> 0 | S24: =J24-M24 -> 0
F25: 9 | G25: Domestic Water Purifier | H25: Nos. | I25: 0.0025 | J25: 2 | K25: =I25*$K$8 -> 511446.88 | L25: =IFERROR(K25/J25,0) -> 255723.44 | M25: ='Schedule 1'!F108 -> 2 | N25: =ROUND(L25*M25,0) -> 511447 | O25: ='Schedule 1'!F109 -> 2 | P25: 511447 | Q25: =M25-O25 -> 0 | R25: =N25-P25 -> 0 | S25: =J25-M25 -> 0
F26: iii | G26: Office Equipment | S26: =J26-M26 -> 0
F27: 1 | G27: Laptops | H27: Nos. | I27: 0.01 | J27: 6 | K27: =I27*$K$8 -> 2045787.5 | L27: =IFERROR(K27/J27,0) -> 340964.58 | M27: ='Schedule 1'!F114 -> 6 | N27: =ROUND(L27*M27,0) -> 2045788 | O27: ='Schedule 1'!F115 -> 6 | P27: 2045788 | Q27: =M27-O27 -> 0 | R27: =N27-P27 -> 0 | S27: =J27-M27 -> 0
F28: 2 | G28: Colour Printer | H28: Nos. | I28: 0.005 | J28: 2 | K28: =I28*$K$8 -> 1022893.8 | L28: =IFERROR(K28/J28,0) -> 511446.88 | M28: ='Schedule 1'!F120 -> 2 | N28: =ROUND(L28*M28,0) -> 1022894 | O28: ='Schedule 1'!F121 -> 2 | P28: 1022894 | Q28: =M28-O28 -> 0 | R28: =N28-P28 -> 0 | S28: =J28-M28 -> 0
F29: =F8+1 -> 102 | G29: Provision (construction) of contractor’s site office, site laboratories, labor camps etc | H29: LS | I29: 0.279 | K29: =I29*$E$8 -> 1.8713925e+08 | S29: =J29-M29 -> 0
F30: a | G30: Completion of Foundation | S30: =J30-M30 -> 0
F31: i | G31: Office | H31: Nos. | I31: 0.1 | J31: 1 | K31: =I31*$K$29 -> 18713925 | L31: =IFERROR(K31/J31,0) -> 18713925 | M31: ='Schedule 1'!F128 -> 1 | N31: =ROUND(L31*M31,0) -> 18713925 | O31: ='Schedule 1'!F129 -> 1 | P31: 18713925 | Q31: =M31-O31 -> 0 | R31: =N31-P31 -> 0 | S31: =J31-M31 -> 0
F32: ii | G32: Laboratory | H32: Nos. | I32: 0.04 | J32: 2 | K32: =I32*$K$29 -> 7485570 | L32: =IFERROR(K32/J32,0) -> 3742785 | M32: ='Schedule 1'!F135 -> 2 | N32: =ROUND(L32*M32,0) -> 7485570 | O32: ='Schedule 1'!F136 -> 2 | P32: 7485570 | Q32: =M32-O32 -> 0 | R32: =N32-P32 -> 0 | S32: =J32-M32 -> 0
F33: iii | G33: Labour Camps | S33: =J33-M33 -> 0
F34: 1 | G34: Building | H34: Nos. | I34: 0.02 | J34: 2 | K34: =I34*$K$29 -> 3742785 | L34: =IFERROR(K34/J34,0) -> 1871392.5 | M34: ='Schedule 1'!F144 -> 2 | N34: =ROUND(L34*M34,0) -> 3742785 | O34: ='Schedule 1'!F145 -> 2 | P34: 3742785 | Q34: =M34-O34 -> 0 | R34: =N34-P34 -> 0 | S34: =J34-M34 -> 0
F35: 2 | G35: Kitchen | H35: Nos. | I35: 0.01 | J35: 2 | K35: =I35*$K$29 -> 1871392.5 | L35: =IFERROR(K35/J35,0) -> 935696.25 | M35: ='Schedule 1'!F151 -> 2 | N35: =ROUND(L35*M35,0) -> 1871393 | O35: ='Schedule 1'!F152 -> 2 | P35: 1871393 | Q35: =M35-O35 -> 0 | R35: =N35-P35 -> 0 | S35: =J35-M35 -> 0
F36: b | G36: Completion of Plinth | S36: =J36-M36 -> 0
F37: i | G37: Office | H37: Nos. | I37: 0.1 | J37: 1 | K37: =I37*$K$29 -> 18713925 | L37: =IFERROR(K37/J37,0) -> 18713925 | M37: ='Schedule 1'!F157 -> 1 | N37: =ROUND(L37*M37,0) -> 18713925 | O37: ='Schedule 1'!F158 -> 1 | P37: 18713925 | Q37: =M37-O37 -> 0 | R37: =N37-P37 -> 0 | S37: =J37-M37 -> 0
F38: ii | G38: Laboratory | H38: Nos. | I38: 0.04 | J38: 2 | K38: =I38*$K$29 -> 7485570 | L38: =IFERROR(K38/J38,0) -> 3742785 | M38: ='Schedule 1'!F164 -> 2 | N38: =ROUND(L38*M38,0) -> 7485570 | O38: ='Schedule 1'!F165 -> 2 | P38: 7485570 | Q38: =M38-O38 -> 0 | R38: =N38-P38 -> 0 | S38: =J38-M38 -> 0
F39: iii | G39: Labour Camps | S39: =J39-M39 -> 0
F40: 1 | G40: Building | H40: Nos. | I40: 0.02 | J40: 2 | K40: =I40*$K$29 -> 3742785 | L40: =IFERROR(K40/J40,0) -> 1871392.5 | M40: ='Schedule 1'!F172 -> 2 | N40: =ROUND(L40*M40,0) -> 3742785 | O40: ='Schedule 1'!F173 -> 2 | P40: 3742785 | Q40: =M40-O40 -> 0 | R40: =N40-P40 -> 0 | S40: =J40-M40 -> 0
F41: 2 | G41: Kitchen | H41: Nos. | I41: 0.01 | J41: 2 | K41: =I41*$K$29 -> 1871392.5 | L41: =IFERROR(K41/J41,0) -> 935696.25 | M41: ='Schedule 1'!F180 -> 2 | N41: =ROUND(L41*M41,0) -> 1871393 | O41: ='Schedule 1'!F181 -> 2 | P41: 1871393 | Q41: =M41-O41 -> 0 | R41: =N41-P41 -> 0 | S41: =J41-M41 -> 0
F42: c | G42: Completion of Walls | S42: =J42-M42 -> 0
...

Sheet MB Details
B1: Item No. | C1: page No | D1: Item Description | E1: UoM | F1: Location | G1: Executed Quantity | H1: RFI No. / Letter No. | I1: Date | J1: IPC No. | K1: Signed date | L1: Remarks
B2: 406.a / 407.c | C2: 75 | D2: Precast - Box girder segments | E2: Nos. | F2: Palashbari | G2: 1 | H2: MPSB/MB/244 | I2: 45940 | J2: IPC - 34 | K2: 45942 | L2: P17-BP-S32a-O | M2: =K2-I2 -> 2
A3: Installation of PSC Box girders/I-Girders at site including installation of Post Tensioning for completion of deck | B3: 506.a.1 | C3: 75 | D3: For Wetland Viaduct - Casting of Deck Panel | E3: Span | F3: Sualkuchi | G3: 1 | H3: MPSB/Str/4959 | I3: 46193 | J3: IPC - 34 | K3: 46193 | L3: PL10 to PL11 | M3: =K3-I3 -> 0
A4: Construction of sub- structure; abutment/piers / lower pylon & Construction of pier- cap/ pier table | B4: 502 & 503.a.2 | C4: 76 | D4: For Wetland Viaduct - On completion of pier-cap / pier table | E4: Nos. | F4: Sualkuchi | G4: 1 | H4: MPSB/Str/4967 | I4: 46193 | J4: IPC - 34 | K4: 46199 | L4: Km 10+636 - PR1 - Piercap | M4: =K4-I4 -> 6
A5: Procurement, testing and supply of post tensioning material to site | B5: 505.a.3 | C5: 76 | D5: For Wetland Viaduct - Final stressing of Girders at site | E5: Nos. | F5: Sualkuchi | G5: 1 | H5: MPSB/Str/5077 | I5: 46206 | J5: IPC - 34 | K5: 46206 | L5: WV2-P3-P4-G2 | M5: =K5-I5 -> 0
B6: 506.a.2 | C6: 77 | D6: For Wetland Viaduct - Deck Panel Erection | E6: Span | F6: Sualkuchi | G6: 3 | H6: MPSB/Str/5079 | I6: 46206 | J6: IPC - 34 | K6: 46206 | L6: PL9 to PL12 | M6: =K6-I6 -> 0
A7: Installation of bearings and expansion joints | B7: 507.a.2 | C7: 77 | D7: For Wetland Viaduct - Bearings - Installation | E7: Nos. | F7: Sualkuchi | G7: 2 | H7: MPSB/Sur/3725 | I7: 46206 | J7: IPC - 34 | K7: 46206 | L7: PR20 | M7: =K7-I7 -> 0
B8: 506.a.1 | C8: 77 | D8: For Wetland Viaduct - Casting of Deck Panel | E8: Span | F8: Sualkuchi | G8: 1 | H8: MPSB/Str/5081 | I8: 46206 | J8: IPC - 34 | K8: 46207 | L8: PL1 to PL2 | M8: =K8-I8 -> 1
B9: 507.a.2 | C9: 78 | D9: For Wetland Viaduct - Bearings - Installation | E9: Nos. | F9: Sualkuchi | G9: 2 | H9: MPSB/Sur/3726 | I9: 46206 | J9: IPC - 34 | K9: 46210 | L9: PR21 | M9: =K9-I9 -> 4
B10: 505.a.3 | C10: 78 | D10: For Wetland Viaduct - Final stressing of Girders at site | E10: Nos. | F10: Sualkuchi | G10: 1 | H10: MPSB/Str/5092 | I10: 46210 | J10: IPC - 34 | K10: 46211 | L10: WV2-P3-P4-G3 | M10: =K10-I10 -> 1
A11: Construction of sub- structure; abutment/ piers / lower pylon | B11: 403.a | C11: 78 | D11: Construction of abutment / piers / lower pylon | E11: Rmt | F11: Palashbari | G11: 2 | H11: MPSB/Str/5108 | I11: 46212 | J11: IPC - 34 | K11: 46214 | L11: P7 - Lower Pylon - 2nd Lift | M11: =K11-I11 -> 2
B12: 403.a | C12: 79 | D12: Construction of abutment / piers / lower pylon | E12: Rmt | F12: Sualkuchi | G12: 2.115 | H12: MPSB/Str/5101 | I12: 46212 | J12: IPC - 34 | K12: 46214 | L12: P25 - Lower Pylon - 2nd Lift | M12: =K12-I12 -> 2
B13: 406.a / 407.c | C13: 79 | D13: Precast - Box girder segments | E13: Nos. | F13: Palashbari | G13: 1 | H13: MPSB/MB/2089 | I13: 46212 | J13: IPC - 34 | K13: 46214 | L13: P16-KS-S09-M | M13: =K13-I13 -> 2
B14: 406.a / 407.c | C14: 79 | D14: Precast - Box girder segments | E14: Nos. | F14: Palashbari | G14: 1 | H14: MPSB/MB/2090 | I14: 46212 | J14: IPC - 34 | K14: 46215 | L14: P9-BP-S04a-O | M14: =K14-I14 -> 3
B15: 406.a / 407.c | C15: 79 | D15: Precast - Box girder segments | E15: Nos. | F15: Palashbari | G15: 1 | H15: MPSB/MB/2087 | I15: 46211 | J15: IPC - 34 | K15: 46215 | L15: P15-BP-S10-O | M15: =K15-I15 -> 4
A16: Construction of PSC Box girders/I-Girders in casting yard | B16: 504.a.1 | C16: 80 | D16: For Wetland Viaduct - Casting of Girders in the precast yard | E16: Nos. | F16: Sualkuchi | G16: 1 | H16: MPSB/Str/5105 | I16: 46212 | J16: IPC - 34 | K16: 46215 | L16: WV1-P1-P2-G3 | M16: =K16-I16 -> 3
B17: 406.a / 407.c | C17: 80 | D17: Precast - Box girder segments | E17: Nos. | F17: Palashbari | G17: 1 | H17: MPSB/MB/2101 | I17: 46213 | J17: IPC - 34 | K17: 46216 | L17: P9-KS-S32-O | M17: =K17-I17 -> 3
A18: Construction of foundation | B18: 501.b.3 | C18: 81 | D18: For Approach Viaduct - On completion of Pile Cap | E18: Nos. | F18: Sualkuchi | G18: 1 | H18: MPSB/Str/5098 | I18: 46211 | J18: IPC - 34 | K18: 46216 | L18: Km 9+352 - PL34 - Pilecap | M18: =K18-I18 -> 5
B19: 406.a / 407.c / 408.c | C19: 81 | D19: Precast - Box girder segments | E19: Nos. | F19: Sualkuchi | G19: 1 | H19: MPSB/MB/2107 | I19: 46213 | J19: IPC - 34 | K19: 46216 | L19: P21-KS-S33-O© | M19: =K19-I19 -> 3
B20: 406.a / 407.c / 408.c | C20: 81 | D20: Precast - Box girder segments | E20: Nos. | F20: Sualkuchi | G20: 1 | H20: MPSB/MB/2113 | I20: 46214 | J20: IPC - 34 | K20: 46217 | L20: P21-BP-S25a-O© | M20: =K20-I20 -> 3
B21: 501.b.2 | C21: 81 | D21: For Approach Viaduct - On completion of Well | E21: Rmt | F21: Palashbari | G21: 1.05 | H21: MPSB/Str/5134 | I21: 46216 | J21: IPC - 34 | K21: 46217 | L21: P4 - 18th Lift | M21: =K21-I21 -> 1
B22: 507.a.2 | C22: 82 | D22: For Wetland Viaduct - Bearings - Installation | E22: Nos. | F22: Sualkuchi | G22: 4 | H22: MPSB/Sur/3761 | I22: 46217 | J22: IPC - 34 | K22: 46217 | L22: PR18 | M22: =K22-I22 -> 0
B23: 406.a / 407.c / 408.c | C23: 82 | D23: Precast - Box girder segments | E23: Nos. | F23: Palashbari | G23: 1 | H23: MPSB/MB/2139 | I23: 46218 | J23: IPC - 34 | K23: 46218 | L23: P16-KS-S10-M© | M23: =K23-I23 -> 0
B24: 502 & 503.a.2 | C24: 82 | D24: For Wetland Viaduct - On completion of pier-cap / pier table | E24: Nos. | F24: Sualkuchi | G24: 1 | H24: MPSB/Str/5112 | I24: 46213 | J24: IPC - 34 | K24: 46218 | L24: Km 10+230 - PL0 - Piercap | M24: =K24-I24 -> 5
B25: 505.b.3 | C25: 83 | D25: For Approach Viaduct - Final Stressing of Girders at site | E25: Nos. | F25: Palashbari | G25: 1 | H25: MPSB/Str/5148 | I25: 46218 | J25: IPC - 34 | K25: 46218 | L25: SAV-P2-P3-G1 | M25: =K25-I25 -> 0
B26: 505.b.3 | C26: 83 | D26: For Approach Viaduct - Final Stressing of Girders at site | E26: Nos. | F26: Palashbari | G26: 1 | H26: MPSB/Str/5149 | I26: 46218 | J26: IPC - 34 | K26: 46218 | L26: SAV-P2-P3-G2 | M26: =K26-I26 -> 0
B27: 506.a.1 | C27: 83 | D27: For Wetland Viaduct - Casting of Deck Panel | E27: Span | F27: Sualkuchi | G27: 1 | H27: MPSB/Str/5135 | I27: 46217 | J27: IPC - 34 | K27: 46218 | L27: PL0 to PL1 | M27: =K27-I27 -> 1
B28: 406.a / 407.c | C28: 84 | D28: Precast - Box girder segments | E28: Nos. | F28: Palashbari | G28: 1 | H28: MPSB/MB/2109 | I28: 46214 | J28: IPC - 34 | K28: 46218 | L28: P16-BP-S17-M | M28: =K28-I28 -> 4
B29: 406.a / 407.c | C29: 84 | D29: Precast - Box girder segments | E29: Nos. | F29: Sualkuchi | G29: 1 | H29: MPSB/MB/2118 | I29: 46216 | J29: IPC - 34 | K29: 46219 | L29: P22-BP-S04-E | M29: =K29-I29 -> 3
B30: 406.a / 407.c / 408.c | C30: 84 | D30: Precast - Box girder segments | E30: Nos. | F30: Palashbari | G30: 1 | H30: MPSB/MB/2116 | I30: 46216 | J30: IPC - 34 | K30: 46219 | L30: P15-BP-S11-O© | M30: =K30-I30 -> 3
... B33: 506.a.1 | C33: 85 | D33: For Wetland Viaduct - Casting of Deck Panel | E33: Span | F33: Sualkuchi | G33: 1 | H33: MPSB/Str/5144 | I33: 46218 | J33: IPC - 34 | K33: 46219 | L33: PR19 to PR20 | M33: =K33-I33 -> 1
A34: Construction of earth retaining structures, culvert & minor structures | B34: 706.a | C34: 86 | D34: Completion of the main structural works excluding finishing works - Culverts | E34: Nos. | F34: Palashbari | G34: 0.5 | H34: MPSB/Str/5143 | I34: 46217 | J34: IPC - 34 | K34: 46219 | L34: Km 4+154 | M34: =K34-I34 -> 2
B35: 403.a | C35: 86 | D35: Construction of abutment / piers / lower pylon | E35: Rmt | F35: Sualkuchi | G35: 0.63 | H35: MPSB/Str/5128 | I35: 46216 | J35: IPC - 34 | K35: 46220 | L35: P29 - Lower Pylon - Starter | M35: =K35-I35 -> 4
B36: 504.a.2 | C36: 86 | D36: For Wetland Viaduct - Erection of Girders at site | E36: Nos. | F36: Sualkuchi | G36: 4 | H36: MPSB/Str/5091 | I36: 46210 | J36: IPC - 34 | K36: 46220 | L36: WV2-P15-P16 (G5 to G8) | M36: =K36-I36 -> 10
B37: 406.a / 407.c | C37: 87 | D37: Precast - Box girder segments | E37: Nos. | F37: Palashbari | G37: 1 | H37: MPSB/MB/2133 | I37: 46217 | J37: IPC - 34 | K37: 46220 | L37: P9-BP-S05a-O | M37: =K37-I37 -> 3
B38: 406.a / 407.c | C38: 87 | D38: Precast - Box girder segments | E38: Nos. | F38: Sualkuchi | G38: 1 | H38: MPSB/MB/2138 | I38: 46218 | J38: IPC - 34 | K38: 46220 | L38: P21-KS-S34-O | M38: =K38-I38 -> 2
B39: 406.a / 407.c | C39: 87 | D39: Precast - Box girder segments | E39: Nos. | F39: Sualkuchi | G39: 1 | H39: MPSB/MB/2154 | I39: 46220 | J39: IPC - 34 | K39: 46221 | L39: P22-BP-S05-E | M39: =K39-I39 -> 1
B40: 406.a / 407.c / 408.c | C40: 87 | D40: Precast - Box girder segments | E40: Nos. | F40: Sualkuchi | G40: 1 | H40: MPSB/MB/2137 | I40: 46218 | J40: IPC - 34 | K40: 46221 | L40: P21-BP-S21a-O© | M40: =K40-I40 -> 3
B41: 504.a.1 | C41: 88 | D41: For Wetland Viaduct - Casting of Girders in the precast yard | E41: Nos. | F41: Sualkuchi | G41: 1 | H41: MPSB/Str/5138 | I41: 46217 | J41: IPC - 34 | K41: 46221 | L41: WV1-P1-P2-G2 | M41: =K41-I41 -> 4
B42: 403.a | C42: 88 | D42: Construction of abutment / piers / lower pylon | E42: Rmt | F42: Palashbari | G42: 4.329 | H42: MPSB/Str/5151 | I42: 46218 | J42: IPC - 34 | K42: 46222 | L42: P8 - Lower Pylon - 7th Lift | M42: =K42-I42 -> 4
...

Sheet Schedule 1
C2: Construction of 4-lane Extra-dosed PSC Bridge over river Brahmaputra connecting Palashbari and Sualkuchi including Viaduct, Approaches and River Training works etc on EPC mode
H3: =CONCATENATE('Detailed breakup'!$O$4," ",'Detailed breakup'!$Q$4) -> Period of bill : 1st Jul'26 to 31st Jul'26
B4: Schedule 1 - Preliminaries and General Items | J4: ='Abs. - PMC (For Print)'!$D$4 -> IPC - 34
B5: Measurement Sheet
B6: Item No. | C6: Item Description | D6: UoM | E6: Location | F6: Executed Quantity | G6: RFI No. / Letter No. / Period | H6: Date | I6: Bill No. | J6: Remarks
B8: 101 | C8: Provision (construction) of office facilities for the Employer
B9: 101.a | C9: Foundation | D9: Nos. | E9: Palashbari | F9: 0.5 | G9: MPSB/Temp/2 | H9: 45450 | I9: IPC - 02
B10: 101.a | C10: Foundation | D10: Nos. | E10: Palashbari | F10: 0.5 | G10: MPSB/Temp/4 | H10: 45451 | I10: IPC - 02
B11: 101.a | C11: Foundation | D11: Nos. | E11: Sualkuchi | F11: 0.5 | G11: MPSB/Temp/15 | H11: 45456 | I11: IPC - 02
B12: 101.a | C12: Foundation | D12: Nos. | E12: Sualkuchi | F12: 0.5 | G12: MPSB/Temp/21 | H12: 45458 | I12: IPC - 02
C14: Cumulative paid upto this Bill | D14: Nos. | F14: =SUM(F9:F13) -> 2
C15: Paid upto previous Bill | D15: Nos. | F15: 2
C16: To be paid in this Bill | D16: Nos. | F16: =F14-F15 -> 0
B18: 101.b | C18: Plinth | D18: Nos. | E18: Palashbari | F18: 1 | G18: MPSB/Temp/5 | H18: 45453 | I18: IPC - 02
B19: 101.b | C19: Plinth | D19: Nos. | E19: Sualkuchi | F19: 1 | G19: MPSB/Temp/39 | H19: 45485 | I19: IPC - 03
C21: Cumulative paid upto this Bill | D21: Nos. | F21: =SUM(F18:F20) -> 2
C22: Paid upto previous Bill | D22: Nos. | F22: 2
C23: To be paid in this Bill | D23: Nos. | F23: =F21-F22 -> 0
B25: 101.c | C25: Walls | D25: Nos. | E25: Palashbari | F25: 1 | G25: MPSB/Temp/11 | H25: 45455 | I25: IPC - 02
B26: 101.c | C26: Walls | D26: Nos. | E26: Sualkuchi | F26: 1 | G26: MPSB/Temp/51 | H26: 45504 | I26: IPC - 03
C28: Cumulative paid upto this Bill | D28: Nos. | F28: =SUM(F25:F27) -> 2
C29: Paid upto previous Bill | D29: Nos. | F29: 2
C30: To be paid in this Bill | D30: Nos. | F30: =F28-F29 -> 0
B32: 101.d | C32: Roof | D32: Nos. | E32: Palashbari | F32: 1 | G32: MPSB/Temp/18 | H32: 45457 | I32: IPC - 02
B33: 101.d | C33: Roof | D33: Nos. | E33: Sualkuchi | F33: 1 | G33: MPSB/Temp/52 | H33: 45504 | I33: IPC - 03
C35: Cumulative paid upto this Bill | D35: Nos. | F35: =SUM(F32:F34) -> 2
C36: Paid upto previous Bill | D36: Nos. | F36: 2
C37: To be paid in this Bill | D37: Nos. | F37: =F35-F36 -> 0
B39: 101.e | C39: Flooring | D39: Nos. | E39: Palashbari | F39: 1 | G39: MPSB/Temp/24 | H39: 45459 | I39: IPC - 02
B40: 101.e | C40: Flooring | D40: Nos. | E40: Sualkuchi | F40: 1 | G40: MPSB/Temp/62 | H40: 45504 | I40: IPC - 03
C42: Cumulative paid upto this Bill | D42: Nos. | F42: =SUM(F39:F41) -> 2
C43: Paid upto previous Bill | D43: Nos. | F43: 2
C44: To be paid in this Bill | D44: Nos. | F44: =F42-F43 -> 0
B46: 101.f.i | C46: Finishing Works - Electrical & Sanitary Works | D46: Nos. | E46: Palashbari | F46: 1 | G46: MPSB/Temp/43 | H46: 45492 | I46: IPC - 03
B47: 101.f.i | C47: Finishing Works - Electrical & Sanitary Works | D47: Nos. | E47: Sualkuchi | F47: 0.9 | G47: MPSB/Temp/64 A | H47: 45526 | I47: IPC - 04
B48: 101.f.i | C48: Finishing Works - Electrical & Sanitary Works | D48: Nos. | E48: Sualkuchi | F48: 0.1 | G48: MPSB/Temp/87 | H48: 45563 | I48: IPC - 05
C50: Cumulative paid upto this Bill | D50: Nos. | F50: =SUM(F46:F49) -> 2
C51: Paid upto previous Bill | D51: Nos. | F51: 2
C52: To be paid in this Bill | D52: Nos. | F52: =F50-F51 -> 0
B54: 101.f.ii.1 | C54: Finishing Works - Office Furniture - Executive Office Desk | D54: Nos. | E54: Palashbari | F54: 4 | G54: MPSB/Temp/48 | H54: 45502 | I54: IPC - 03
...

Sheet Schedule 2
C2: Construction of 4-lane Extra-dosed PSC Bridge over river Brahmaputra connecting Palashbari and Sualkuchi including Viaduct, Approaches and River Training works etc on EPC mode
H3: ='Schedule 1'!H3 -> Period of bill : 1st Jul'26 to 31st Jul'26
B4: Schedule 2 - Validation of Survey Data, Investigation, Design and As-Built Drawings | J4: ='Schedule 1'!J4 -> IPC - 34
B5: Measurement Sheet
B6: Item No. | C6: Item Description | D6: UoM | E6: Location | F6: Executed Quantity | G6: RFI No. / Letter No. / Period | H6: Date | I6: Bill No. | J6: Remarks
B8: 201 | C8: Site survey, establishment of bench marks, validation of ROW, identification of borrow areas
B9: 201.a | C9: Establishment of Bench Marks | D9: Kms | F9: 12.21 | G9: MPSB/SUR/1 | H9: 45450 | I9: IPC - 02
C11: Cumulative paid upto this Bill | D11: Kms | F11: =ROUND(SUM(F9:F10),3) -> 12.21
C12: Paid upto previous Bill | D12: Kms | F12: =12.21 -> 12.21
C13: To be paid in this Bill | D13: Kms | F13: =F11-F12 -> 0
B15: 201.b | C15: Completion of Site Survey | D15: Kms | F15: 12.21 | G15: MPSB/SUR/3 | H15: 45458 | I15: IPC - 02
C17: Cumulative paid upto this Bill | D17: Kms | F17: =ROUND(SUM(F15:F16),3) -> 12.21
C18: Paid upto previous Bill | D18: Kms | F18: =12.21 -> 12.21
C19: To be paid in this Bill | D19: Kms | F19: =F17-F18 -> 0
B21: 201.c | C21: Validation of ROW | D21: Kms | F21: =5.6 -> 5.6 | G21: MPSB/SUR/4 | H21: 45461 | I21: IPC - 02
B22: 201.c | C22: Validation of ROW | D22: Kms | F22: =12.21-F21 -> 6.61 | G22: MPSB/SUR/5 | H22: 45462 | I22: IPC - 02
C24: Cumulative paid upto this Bill | D24: Kms | F24: =ROUND(SUM(F21:F23),3) -> 12.21
C25: Paid upto previous Bill | D25: Kms | F25: =12.21 -> 12.21
C26: To be paid in this Bill | D26: Kms | F26: =F24-F25 -> 0
B28: 201.d | C28: Identification of Borrow Areas | D28: Nos. | F28: 2 | G28: GM/MM/86-B(40)/Pt.VIII/214-17 GM/MM/86-B(40)/Pt. V/388-92 | H28: 31-May-24 06-Jun-24 | I28: IPC - 03
B29: 201.d | C29: Identification of Borrow Areas | D29: Nos. | F29: 3 | G29: GM/MM/86-B(40)/Pt. V/378-82 GM/MM/86-B(40)/Pt.VIII/383-87 GM/MM/86-B(40)/Pt.VIII/373-77 | H29: 06-Jun-24 06-Jun-24 06-Jun-24 | I29: IPC - 04
C31: Cumulative paid upto this Bill | D31: Nos. | F31: =ROUND(SUM(F28:F30),3) -> 5
C32: Paid upto previous Bill | D32: Nos. | F32: 5
C33: To be paid in this Bill | D33: Nos. | F33: =F31-F32 -> 0
B35: 202 | C35: Site data collection, Detailed Geotechnical and Hydrological investigations and report submission & approval
B36: 202.a.i | C36: Completion of Topographical Survey - Submission | D36: Kms | F36: 12.21 | G36: MPSB/SUR/2 | H36: 45455 | I36: IPC - 02
C38: Cumulative paid upto this Bill | D38: Kms | F38: =ROUND(SUM(F36:F37),3) -> 12.21
C39: Paid upto previous Bill | D39: Kms | F39: 12.21
C40: To be paid in this Bill | D40: Kms | F40: =F38-F39 -> 0
B42: 202.a.ii | C42: Completion of Topographical Survey - Approval | D42: Kms | F42: 12.21 | G42: RI-1624-SO-HWB-BR-S&I-0010-R0-254 | H42: 45516 | I42: IPC - 04
C44: Cumulative paid upto this Bill | D44: Kms | F44: =ROUND(SUM(F42:F43),3) -> 12.21
C45: Paid upto previous Bill | D45: Kms | F45: 12.21
C46: To be paid in this Bill | D46: Kms | F46: =F44-F45 -> 0
B48: 202.b.i | C48: Detailed Geotechnical Investigation - Submission | D48: Nos. | F48: 2 | G48: MPSB/QAQC/1 | H48: 45450 | I48: IPC - 02
B49: 202.b.i | C49: Detailed Geotechnical Investigation - Submission | D49: Nos. | F49: 3 | G49: MPSB/QAQC/2 | H49: 45451 | I49: IPC - 02
B50: 202.b.i | C50: Detailed Geotechnical Investigation - Submission | D50: Nos. | F50: 4 | G50: MPSB/QAQC/3 | H50: 45453 | I50: IPC - 02
B51: 202.b.i | C51: Detailed Geotechnical Investigation - Submission | D51: Nos. | F51: 1 | G51: MPSB/QAQC/4 | H51: 45454 | I51: IPC - 02
B52: 202.b.i | C52: Detailed Geotechnical Investigation - Submission | D52: Nos. | F52: 5 | G52: MPSB/QAQC/5 | H52: 45455 | I52: IPC - 02
B53: 202.b.i | C53: Detailed Geotechnical Investigation - Submission | D53: Nos. | F53: 5 | G53: MPSB/QAQC/6 | H53: 45456 | I53: IPC - 02
B54: 202.b.i | C54: Detailed Geotechnical Investigation - Submission | D54: Nos. | F54: 5 | G54: MPSB/QAQC/7 | H54: 45457 | I54: IPC - 02
...

Sheet Schedule 3
C2: Construction of 4-lane Extra-dosed PSC Bridge over river Brahmaputra connecting Palashbari and Sualkuchi including Viaduct, Approaches and River Training works etc on EPC mode
H3: ='Schedule 2'!H3 -> Period of bill : 1st Jul'26 to 31st Jul'26
B4: Schedule 3 - Enabling Works for Main Works | J4: ='Schedule 1'!J4 -> IPC - 34
B5: Measurement Sheet
B6: Item No. | C6: Item Description | D6: UoM | E6: Location | F6: Executed Quantity | G6: RFI No. / Letter No. / Period | H6: Date | I6: Bill No. | J6: Remarks
B8: 301 | C8: Construction of temporary jetties/ platforms (TAB) / load out jetties etc for marine working
B9: 301.a | C9: Supply of TAB material at site | D9: MT | E9: Palashbari | F9: 1929.425 | G9: MPSB/Temp/7 | H9: 45453 | I9: IPC - 02
B10: 301.a | C10: Supply of TAB material at site | D10: MT | E10: Sualkuchi | F10: 1353.325 | G10: MPSB/Temp/10 | H10: 45454 | I10: IPC - 02
B11: 301.a | C11: Supply of TAB material at site | D11: MT | E11: Palashbari | F11: 616.6281 | G11: MPSB/Temp/49 | H11: 45502 | I11: IPC - 03
C13: Cumulative paid upto this Bill | D13: MT | F13: =SUM(F9:F12) -> 3899.3781
C14: Paid upto previous Bill | D14: MT | F14: 3899.3781
C15: To be paid in this Bill | D15: MT | F15: =F13-F14 -> 0
B17: 301.b | C17: Installation of TAB | D17: Rmt | E17: Palashbari | F17: 174.4 | G17: MPSB/Temp/72 | H17: 45533 | I17: IPC - 04 | J17: Km 5+558.6 - Km 5+733
B18: 301.b | C18: Installation of TAB | D18: Rmt | E18: Sualkuchi | F18: 36 | G18: MPSB/Temp/79 | H18: 45535 | I18: IPC - 04 | J18: Km 9+216 - Km 9+180
B19: 301.b | C19: Installation of TAB | D19: Rmt | E19: Palashbari | F19: =5756-5733 -> 23 | G19: MPSB/Temp/92 | H19: 45563 | I19: IPC - 05 | J19: Km 5+733 - Km 5+756
B20: 301.b | C20: Installation of TAB | D20: Rmt | E20: Palashbari | F20: =5781-5756 -> 25 | G20: MPSB/Temp/95 | H20: 45565 | I20: IPC - 05 | J20: Km 5+756 - Km 5+781
B21: 301.b | C21: Installation of TAB | D21: Rmt | E21: Sualkuchi | F21: =9182-9159 -> 23 | G21: MPSB/Temp/81 | H21: 45546 | I21: IPC - 05 | J21: Km 9+182 - Km 9+159
B22: 301.b | C22: Installation of TAB | D22: Rmt | E22: Sualkuchi | F22: =9159-9105 -> 54 | G22: MPSB/Temp/91 | H22: 45563 | I22: IPC - 05 | J22: Km 9+159 - Km 9+105
B23: 301.b | C23: Installation of TAB | D23: Rmt | E23: Sualkuchi | F23: =9105-9092 -> 13 | G23: MPSB/Temp/96 | H23: 45565 | I23: IPC - 05 | J23: Km 9+105 - Km 9+092
B24: 301.b | C24: Installation of TAB | D24: Rmt | E24: Sualkuchi | F24: =9080-9017.5 -> 62.5 | G24: MPSB/Temp/100 | H24: 45594 | I24: IPC - 07 | J24: Km 9+092 - Km 9+107.5
B25: 301.b | C25: Installation of TAB | D25: Rmt | E25: Palashbari | F25: =5829-5781 -> 48 | G25: MPSB/Temp/102 | H25: 45594 | I25: IPC - 07 | J25: Km 5+781 - Km 5+829
B26: 301.b | C26: Installation of TAB | D26: Rmt | E26: Sualkuchi | F26: =9017.5-8992 -> 25.5 | G26: MPSB/Temp/103 | H26: 45596 | I26: IPC - 07 | J26: Km 9+107.5 - Km 8+992
B27: 301.b | C27: Installation of TAB | D27: Rmt | E27: Palashbari | F27: =5854-5829 -> 25 | G27: MPSB/Temp/104 | H27: 45596 | I27: IPC - 07 | J27: Km 5+829 - Km 5+854
B28: 301.b | C28: Installation of TAB | D28: Rmt | E28: Sualkuchi | F28: =8992-8956 -> 36 | G28: MPSB/Temp/109 | H28: 45611 | I28: IPC - 08 | J28: Km 8+992 - Km 8+956
B29: 301.b | C29: Installation of TAB | D29: Rmt | E29: Palashbari | F29: =5929-5854 -> 75 | G29: MPSB/Temp/110 | H29: 45624 | I29: IPC - 08 | J29: Km 5+854 - Km 5+929
B30: 301.b | C30: Installation of TAB | D30: Rmt | E30: Sualkuchi | F30: =8879.9-8857.9 -> 22 | G30: MPSB/Temp/113 | H30: 45626 | I30: IPC - 08 | J30: Km 8+879.9 - Km 8+857.9
B31: 301.b | C31: Installation of TAB | D31: Rmt | E31: Palashbari | F31: =5959-5929.4 -> 29.6 | G31: MPSB/Temp/114 | H31: 45626 | I31: IPC - 08 | J31: Km 5+929 - Km 5+959
C33: Cumulative paid upto this Bill | D33: Rmt | F33: =SUM(F17:F32) -> 672
C34: Paid upto previous Bill | D34: Rmt | F34: 672
C35: To be paid in this Bill | D35: Rmt | F35: =F33-F34 -> 0
B37: 302 | C37: Establishment of batching plant, crusher (if any), rebar yards, formwork shops, fabrication shops etc for main works
B38: 302.a.i | C38: Establishment of Batching Plants - Receipt of Equipment | D38: Nos. | E38: Palashbari | F38: 2 | G38: MPSB/Gen/1 | H38: 45454 | I38: IPC - 02
B39: 302.a.i | C39: Establishment of Batching Plants - Receipt of Equipment | D39: Nos. | E39: Sualkuchi | F39: 2 | G39: MPSB/Gen/3 | H39: 45462 | I39: IPC - 02
C41: Cumulative paid upto this Bill | D41: Nos. | F41: =SUM(F38:F40) -> 4
C42: Paid upto previous Bill | D42: Nos. | F42: 4
C43: To be paid in this Bill | D43: Nos. | F43: =F41-F42 -> 0
A45: c | B45: 302.a.ii | C45: Establishment of Batching Plants - Foundation | D45: Nos. | E45: Sualkuchi | F45: 1 | G45: MPSB/Gen/5 | H45: 45473 | I45: IPC - 02
B46: 302.a.ii | C46: Establishment of Batching Plants - Foundation | D46: Nos. | E46: Palashbari | F46: 1 | G46: MPSB/Gen/6 | H46: 45473 | I46: IPC - 02
B47: 302.a.ii | C47: Establishment of Batching Plants - Foundation | D47: Nos. | E47: Sualkuchi | F47: 1 | G47: MPSB/Gen/10 | H47: 45688 | I47: IPC - 10
B48: 302.a.ii | C48: Establishment of Batching Plants - Foundation | D48: Nos. | E48: Palashbari | F48: 1 | G48: MPSB/Gen/12 | H48: 45702 | I48: IPC - 11
...

Sheet Segment Summary
A1: Main Bridge - Segments Scope Vs Casting
A3: P6 | C3: P7 | E3: P8 | G3: P9 | I3: P10 | K3: P11 | M3: P12 | O3: P13 | Q3: P14 | S3: P15 | U3: P16 | W3: P17 | Y3: P18
A4: Seg. ID | B4: Casted in | C4: Seg. ID | D4: Casted in | E4: Seg. ID | F4: Casted in | G4: Seg. ID | H4: Casted in | I4: Seg. ID | J4: Casted in | K4: Seg. ID | L4: Casted in | M4: Seg. ID | N4: Casted in | O4: Seg. ID | P4: Casted in | Q4: Seg. ID | R4: Casted in | S4: Seg. ID | T4: Casted in | U4: Seg. ID | V4: Casted in | W4: Seg. ID | X4: Casted in | Y4: Seg. ID | Z4: Casted in
A5: P6-S01a-E | B5: =VLOOKUP(A5,'Segment Abs.'!$B:$C,2,0) -> #N/A | C5: P7-S01a-O | D5: =VLOOKUP(C5,'Segment Abs.'!$B:$C,2,0) -> #N/A | E5: P8-S01a-M | F5: =VLOOKUP(E5,'Segment Abs.'!$B:$C,2,0) -> #N/A | G5: P9-S01a-O | H5: =VLOOKUP(G5,'Segment Abs.'!$B:$C,2,0) -> #N/A | I5: P10-S01a-E | J5: =VLOOKUP(I5,'Segment Abs.'!$B:$C,2,0) -> #N/A | K5: P11-S01a-O | L5: =VLOOKUP(K5,'Segment Abs.'!$B:$C,2,0) -> #N/A | M5: P12-S01a-M | N5: =VLOOKUP(M5,'Segment Abs.'!$B:$C,2,0) -> #N/A | O5: P13-S01a-O | P5: =VLOOKUP(O5,'Segment Abs.'!$B:$C,2,0) -> #N/A | Q5: P14-S01a-E | R5: =VLOOKUP(Q5,'Segment Abs.'!$B:$C,2,0) -> #N/A | S5: P15-S01a-O | T5: =VLOOKUP(S5,'Segment Abs.'!$B:$C,2,0) -> #N/A | U5: P16-S01a-M | V5: =VLOOKUP(U5,'Segment Abs.'!$B:$C,2,0) -> #N/A | W5: P17-S01a-O | X5: =VLOOKUP(W5,'Segment Abs.'!$B:$C,2,0) -> #N/A | Y5: P18-S01a-E | Z5: =VLOOKUP(Y5,'Segment Abs.'!$B:$C,2,0) -> #N/A
A6: P6-S01-E | B6: =VLOOKUP(A6,'Segment Abs.'!$B:$C,2,0) -> #N/A | C6: P7-S02a-O | D6: =VLOOKUP(C6,'Segment Abs.'!$B:$C,2,0) -> #N/A | E6: P8-S02a-M | F6: =VLOOKUP(E6,'Segment Abs.'!$B:$C,2,0) -> #N/A | G6: P9-S02a-O | H6: =VLOOKUP(G6,'Segment Abs.'!$B:$C,2,0) -> #N/A | I6: P10-S01-E | J6: =VLOOKUP(I6,'Segment Abs.'!$B:$C,2,0) -> #N/A | K6: P11-S02a-O | L6: =VLOOKUP(K6,'Segment Abs.'!$B:$C,2,0) -> #N/A | M6: P12-S02a-M | N6: =VLOOKUP(M6,'Segment Abs.'!$B:$C,2,0) -> #N/A | O6: P13-S02a-O | P6: =VLOOKUP(O6,'Segment Abs.'!$B:$C,2,0) -> #N/A | Q6: P14-S01-E | R6: =VLOOKUP(Q6,'Segment Abs.'!$B:$C,2,0) -> #N/A | S6: P15-S02a-O | T6: =VLOOKUP(S6,'Segment Abs.'!$B:$C,2,0) -> #N/A | U6: P16-S02a-M | V6: =VLOOKUP(U6,'Segment Abs.'!$B:$C,2,0) -> #N/A | W6: P17-S02a-O | X6: =VLOOKUP(W6,'Segment Abs.'!$B:$C,2,0) -> #N/A | Y6: P18-S01-E | Z6: =VLOOKUP(Y6,'Segment Abs.'!$B:$C,2,0) -> #N/A
A7: P6-S02a-E | B7: =VLOOKUP(A7,'Segment Abs.'!$B:$C,2,0) -> #N/A | C7: P7-S03a-O | D7: =VLOOKUP(C7,'Segment Abs.'!$B:$C,2,0) -> #N/A | E7: P8-S03a-M | F7: =VLOOKUP(E7,'Segment Abs.'!$B:$C,2,0) -> #N/A | G7: P9-S03a-O | H7: =VLOOKUP(G7,'Segment Abs.'!$B:$C,2,0) -> #N/A | I7: P10-S02a-E | J7: =VLOOKUP(I7,'Segment Abs.'!$B:$C,2,0) -> #N/A | K7: P11-S03a-O | L7: =VLOOKUP(K7,'Segment Abs.'!$B:$C,2,0) -> #N/A | M7: P12-S03a-M | N7: =VLOOKUP(M7,'Segment Abs.'!$B:$C,2,0) -> #N/A | O7: P13-S03a-O | P7: =VLOOKUP(O7,'Segment Abs.'!$B:$C,2,0) -> #N/A | Q7: P14-S02a-E | R7: =VLOOKUP(Q7,'Segment Abs.'!$B:$C,2,0) -> #N/A | S7: P15-S03a-O | T7: =VLOOKUP(S7,'Segment Abs.'!$B:$C,2,0) -> #N/A | U7: P16-S03a-M | V7: =VLOOKUP(U7,'Segment Abs.'!$B:$C,2,0) -> #N/A | W7: P17-S03a-O | X7: =VLOOKUP(W7,'Segment Abs.'!$B:$C,2,0) -> #N/A | Y7: P18-S02a-E | Z7: =VLOOKUP(Y7,'Segment Abs.'!$B:$C,2,0) -> #N/A
A8: P6-S03a-E | B8: =VLOOKUP(A8,'Segment Abs.'!$B:$C,2,0) -> #N/A | C8: P7-S04a-O | D8: =VLOOKUP(C8,'Segment Abs.'!$B:$C,2,0) -> #N/A | E8: P8-S04a-M | F8: =VLOOKUP(E8,'Segment Abs.'!$B:$C,2,0) -> #N/A | G8: P9-S04a-O | H8: =VLOOKUP(G8,'Segment Abs.'!$B:$C,2,0) -> #N/A | I8: P10-S03a-E | J8: =VLOOKUP(I8,'Segment Abs.'!$B:$C,2,0) -> #N/A | K8: P11-S04a-O | L8: =VLOOKUP(K8,'Segment Abs.'!$B:$C,2,0) -> #N/A | M8: P12-S04a-M | N8: =VLOOKUP(M8,'Segment Abs.'!$B:$C,2,0) -> #N/A | O8: P13-S04a-O | P8: =VLOOKUP(O8,'Segment Abs.'!$B:$C,2,0) -> #N/A | Q8: P14-S03a-E | R8: =VLOOKUP(Q8,'Segment Abs.'!$B:$C,2,0) -> #N/A | S8: P15-S04a-O | T8: =VLOOKUP(S8,'Segment Abs.'!$B:$C,2,0) -> #N/A | U8: P16-S04a-M | V8: =VLOOKUP(U8,'Segment Abs.'!$B:$C,2,0) -> #N/A | W8: P17-S04a-O | X8: =VLOOKUP(W8,'Segment Abs.'!$B:$C,2,0) -> #N/A | Y8: P18-S03a-E | Z8: =VLOOKUP(Y8,'Segment Abs.'!$B:$C,2,0) -> #N/A
A9: P6-S04a-E | B9: =VLOOKUP(A9,'Segment Abs.'!$B:$C,2,0) -> #N/A | C9: P7-S05a-O | D9: =VLOOKUP(C9,'Segment Abs.'!$B:$C,2,0) -> #N/A | E9: P8-S05a-M | F9: =VLOOKUP(E9,'Segment Abs.'!$B:$C,2,0) -> #N/A | G9: P9-S05a-O | H9: =VLOOKUP(G9,'Segment Abs.'!$B:$C,2,0) -> #N/A | I9: P10-S04a-E | J9: =VLOOKUP(I9,'Segment Abs.'!$B:$C,2,0) -> #N/A | K9: P11-S05a-O | L9: =VLOOKUP(K9,'Segment Abs.'!$B:$C,2,0) -> #N/A | M9: P12-S05a-M | N9: =VLOOKUP(M9,'Segment Abs.'!$B:$C,2,0) -> #N/A | O9: P13-S05a-O | P9: =VLOOKUP(O9,'Segment Abs.'!$B:$C,2,0) -> #N/A | Q9: P14-S04a-E | R9: =VLOOKUP(Q9,'Segment Abs.'!$B:$C,2,0) -> #N/A | S9: P15-S05a-O | T9: =VLOOKUP(S9,'Segment Abs.'!$B:$C,2,0) -> #N/A | U9: P16-S05a-M | V9: =VLOOKUP(U9,'Segment Abs.'!$B:$C,2,0) -> #N/A | W9: P17-S05a-O | X9: =VLOOKUP(W9,'Segment Abs.'!$B:$C,2,0) -> #N/A | Y9: P18-S04a-E | Z9: =VLOOKUP(Y9,'Segment Abs.'!$B:$C,2,0) -> #N/A
A10: P6-S05a-E | B10: =VLOOKUP(A10,'Segment Abs.'!$B:$C,2,0) -> #N/A | C10: P7-S06a-O | D10: =VLOOKUP(C10,'Segment Abs.'!$B:$C,2,0) -> #N/A | E10: P8-S06a-M | F10: =VLOOKUP(E10,'Segment Abs.'!$B:$C,2,0) -> #N/A | G10: P9-S06a-O | H10: =VLOOKUP(G10,'Segment Abs.'!$B:$C,2,0) -> #N/A | I10: P10-S05a-E | J10: =VLOOKUP(I10,'Segment Abs.'!$B:$C,2,0) -> #N/A | K10: P11-S06a-O | L10: =VLOOKUP(K10,'Segment Abs.'!$B:$C,2,0) -> #N/A | M10: P12-S06a-M | N10: =VLOOKUP(M10,'Segment Abs.'!$B:$C,2,0) -> #N/A | O10: P13-S06a-O | P10: =VLOOKUP(O10,'Segment Abs.'!$B:$C,2,0) -> #N/A | Q10: P14-S05a-E | R10: =VLOOKUP(Q10,'Segment Abs.'!$B:$C,2,0) -> #N/A | S10: P15-S06a-O | T10: =VLOOKUP(S10,'Segment Abs.'!$B:$C,2,0) -> #N/A | U10: P16-S06a-M | V10: =VLOOKUP(U10,'Segment Abs.'!$B:$C,2,0) -> #N/A | W10: P17-S06a-O | X10: =VLOOKUP(W10,'Segment Abs.'!$B:$C,2,0) -> #N/A | Y10: P18-S05a-E | Z10: =VLOOKUP(Y10,'Segment Abs.'!$B:$C,2,0) -> #N/A
A11: P6-S06a-E | B11: =VLOOKUP(A11,'Segment Abs.'!$B:$C,2,0) -> #N/A | C11: P7-S07a-O | D11: =VLOOKUP(C11,'Segment Abs.'!$B:$C,2,0) -> #N/A | E11: P8-S07a-M | F11: =VLOOKUP(E11,'Segment Abs.'!$B:$C,2,0) -> #N/A | G11: P9-S07a-O | H11: =VLOOKUP(G11,'Segment Abs.'!$B:$C,2,0) -> #N/A | I11: P10-S06a-E | J11: =VLOOKUP(I11,'Segment Abs.'!$B:$C,2,0) -> #N/A | K11: P11-S07a-O | L11: =VLOOKUP(K11,'Segment Abs.'!$B:$C,2,0) -> #N/A | M11: P12-S07a-M | N11: =VLOOKUP(M11,'Segment Abs.'!$B:$C,2,0) -> #N/A | O11: P13-S07a-O | P11: =VLOOKUP(O11,'Segment Abs.'!$B:$C,2,0) -> #N/A | Q11: P14-S06a-E | R11: =VLOOKUP(Q11,'Segment Abs.'!$B:$C,2,0) -> #N/A | S11: P15-S07a-O | T11: =VLOOKUP(S11,'Segment Abs.'!$B:$C,2,0) -> #N/A | U11: P16-S07a-M | V11: =VLOOKUP(U11,'Segment Abs.'!$B:$C,2,0) -> #N/A | W11: P17-S07a-O | X11: =VLOOKUP(W11,'Segment Abs.'!$B:$C,2,0) -> #N/A | Y11: P18-S06a-E | Z11: =VLOOKUP(Y11,'Segment Abs.'!$B:$C,2,0) -> #N/A
A12: P6-S34a-O | B12: =VLOOKUP(A12,'Segment Abs.'!$B:$C,2,0) -> #N/A | C12: P7-S08a-O | D12: =VLOOKUP(C12,'Segment Abs.'!$B:$C,2,0) -> #N/A | E12: P8-S08a-M© | F12: =VLOOKUP(E12,'Segment Abs.'!$B:$C,2,0) -> #N/A | G12: P9-S08a-O | H12: =VLOOKUP(G12,'Segment Abs.'!$B:$C,2,0) -> #N/A | I12: P10-S34a-O | J12: =VLOOKUP(I12,'Segment Abs.'!$B:$C,2,0) -> #N/A | K12: P11-S08a-O | L12: =VLOOKUP(K12,'Segment Abs.'!$B:$C,2,0) -> #N/A | M12: P12-S08a-M© | N12: =VLOOKUP(M12,'Segment Abs.'!$B:$C,2,0) -> #N/A | O12: P13-S08a-O | P12: =VLOOKUP(O12,'Segment Abs.'!$B:$C,2,0) -> #N/A | Q12: P14-S34a-O | R12: =VLOOKUP(Q12,'Segment Abs.'!$B:$C,2,0) -> #N/A | S12: P15-S08a-O | T12: =VLOOKUP(S12,'Segment Abs.'!$B:$C,2,0) -> #N/A | U12: P16-S08a-M© | V12: =VLOOKUP(U12,'Segment Abs.'!$B:$C,2,0) -> #N/A | W12: P17-S08a-O | X12: =VLOOKUP(W12,'Segment Abs.'!$B:$C,2,0) -> #N/A | Y12: P18-S34a-O | Z12: =VLOOKUP(Y12,'Segment Abs.'!$B:$C,2,0) -> #N/A
